Traceback (most recent call last):
  File "C:\Users\KELLY\miniconda3\Lib\site-packages\jupyter_cache\executors\utils.py", line 58, in single_nb_execution
    executenb(
  File "C:\Users\KELLY\miniconda3\Lib\site-packages\nbclient\client.py", line 1314, in execute
    return NotebookClient(nb=nb, resources=resources, km=km, **kwargs).execute()
           ^^^^^^^^^^^^^^^^^^^^^^^^^^^^^^^^^^^^^^^^^^^^^^^^^^^^^^^^^^^^^^^^^^^^^
  File "C:\Users\KELLY\miniconda3\Lib\site-packages\jupyter_core\utils\__init__.py", line 165, in wrapped
    return loop.run_until_complete(inner)
           ^^^^^^^^^^^^^^^^^^^^^^^^^^^^^^
  File "C:\Users\KELLY\miniconda3\Lib\asyncio\base_events.py", line 687, in run_until_complete
    return future.result()
           ^^^^^^^^^^^^^^^
  File "C:\Users\KELLY\miniconda3\Lib\site-packages\nbclient\client.py", line 709, in async_execute
    await self.async_execute_cell(
  File "C:\Users\KELLY\miniconda3\Lib\site-packages\nbclient\client.py", line 1062, in async_execute_cell
    await self._check_raise_for_error(cell, cell_index, exec_reply)
  File "C:\Users\KELLY\miniconda3\Lib\site-packages\nbclient\client.py", line 918, in _check_raise_for_error
    raise CellExecutionError.from_cell_and_msg(cell, exec_reply_content)
nbclient.exceptions.CellExecutionError: An error occurred while executing the following cell:
------------------
mejor_logreg_score = 0
mejor_logreg_params = None

for C in [0.001, 0.01, 0.1, 1, 10, 100]:
    logreg = LogisticRegression(C=C, max=10000)
    logreg.fit(X_train, y_train)
    
    scores = cross_val_score(logreg, X_train, y_train, cv=5, scoring='f1')
    avg = np.mean(scores)
    
    if avg > mejor_logreg_score:
        mejor_logreg_score = avg
        mejor_logreg_params = C

logreg_b = LogisticRegression(C=mejor_logreg_params, max=10000)
logreg_b.fit(X_train, y_train)
man_pred_logreg = logreg_b.predict(X_test)
man_prob_logreg = logreg_b.predict_proba(X_test)[:, 1]

logreg_precision = precision_score(y_test, man_pred_logreg)
logreg_recall = recall_score(y_test, man_pred_logreg)
logreg_f1 = f1_score(y_test, man_pred_logreg)
logreg_auc = roc_auc_score(y_test, man_prob_logreg)

print(f"mejores parametros de Regresion logistica: C={mejor_logreg_params}")
print(f"Logistic Regression Precision: {logreg_precision:.5f}, Recall: {logreg_recall:.5f}, F1-Score: {logreg_f1:.5f}, AUC: {logreg_auc:.5f}")
------------------


[1;31m---------------------------------------------------------------------------[0m
[1;31mTypeError[0m                                 Traceback (most recent call last)
Cell [1;32mIn[7], line 5[0m
[0;32m      2[0m mejor_logreg_params [38;5;241m=[39m [38;5;28;01mNone[39;00m
[0;32m      4[0m [38;5;28;01mfor[39;00m C [38;5;129;01min[39;00m [[38;5;241m0.001[39m, [38;5;241m0.01[39m, [38;5;241m0.1[39m, [38;5;241m1[39m, [38;5;241m10[39m, [38;5;241m100[39m]:
[1;32m----> 5[0m     logreg [38;5;241m=[39m [43mLogisticRegression[49m[43m([49m[43mC[49m[38;5;241;43m=[39;49m[43mC[49m[43m,[49m[43m [49m[38;5;28;43mmax[39;49m[38;5;241;43m=[39;49m[38;5;241;43m10000[39;49m[43m)[49m
[0;32m      6[0m     logreg[38;5;241m.[39mfit(X_train, y_train)
[0;32m      8[0m     scores [38;5;241m=[39m cross_val_score(logreg, X_train, y_train, cv[38;5;241m=[39m[38;5;241m5[39m, scoring[38;5;241m=[39m[38;5;124m'[39m[38;5;124mf1[39m[38;5;124m'[39m)

[1;31mTypeError[0m: LogisticRegression.__init__() got an unexpected keyword argument 'max'

